2022-03-31 08:29:29,673 ERROR: Exception on /user/peterchan [GET] [in C:\Python310\lib\site-packages\flask\app.py:1457]
Traceback (most recent call last):
  File "C:\Python310\lib\site-packages\flask\app.py", line 2073, in wsgi_app
    response = self.full_dispatch_request()
  File "C:\Python310\lib\site-packages\flask\app.py", line 1518, in full_dispatch_request
    rv = self.handle_user_exception(e)
  File "C:\Python310\lib\site-packages\flask\app.py", line 1516, in full_dispatch_request
    rv = self.dispatch_request()
  File "C:\Python310\lib\site-packages\flask\app.py", line 1502, in dispatch_request
    return self.ensure_sync(self.view_functions[rule.endpoint])(**req.view_args)
  File "C:\Python310\lib\site-packages\flask_login\utils.py", line 272, in decorated_view
    return func(*args, **kwargs)
  File "C:\Users\Administrator\PycharmProjects\microblog\app\main\routes.py", line 68, in user
    return render_template('user.html', user=user, posts=posts.items,
  File "C:\Python310\lib\site-packages\flask\templating.py", line 147, in render_template
    return _render(
  File "C:\Python310\lib\site-packages\flask\templating.py", line 128, in _render
    rv = template.render(context)
  File "C:\Python310\lib\site-packages\jinja2\environment.py", line 1291, in render
    self.environment.handle_exception()
  File "C:\Python310\lib\site-packages\jinja2\environment.py", line 925, in handle_exception
    raise rewrite_traceback_stack(source=source)
  File "C:\Users\Administrator\PycharmProjects\microblog\app\templates\user.html", line 1, in top-level template code
    {% extends "base.html" %}
  File "C:\Users\Administrator\PycharmProjects\microblog\app\templates\base.html", line 1, in top-level template code
    {% extends 'bootstrap/base.html' %}
  File "C:\Python310\lib\site-packages\flask_bootstrap\templates\bootstrap\base.html", line 1, in top-level template code
    {% block doc -%}
  File "C:\Python310\lib\site-packages\flask_bootstrap\templates\bootstrap\base.html", line 4, in block 'doc'
    {%- block html %}
  File "C:\Python310\lib\site-packages\flask_bootstrap\templates\bootstrap\base.html", line 20, in block 'html'
    {% block body -%}
  File "C:\Python310\lib\site-packages\flask_bootstrap\templates\bootstrap\base.html", line 23, in block 'body'
    {% block content -%}
  File "C:\Users\Administrator\PycharmProjects\microblog\app\templates\base.html", line 50, in block 'content'
    {% block current_app_content %}{% endblock %}
  File "C:\Users\Administrator\PycharmProjects\microblog\app\templates\user.html", line 25, in block 'current_app_content'
    {% include '_post.html' %}
  File "C:\Users\Administrator\PycharmProjects\microblog\app\templates\_post.html", line 4, in top-level template code
    <a href="{{ url_for('user', username=post.author.username) }}">
  File "C:\Python310\lib\site-packages\flask\helpers.py", line 338, in url_for
    return appctx.app.handle_url_build_error(error, endpoint, values)
  File "C:\Python310\lib\site-packages\flask\helpers.py", line 325, in url_for
    rv = url_adapter.build(
  File "C:\Python310\lib\site-packages\werkzeug\routing.py", line 2315, in build
    raise BuildError(endpoint, values, method, self)
werkzeug.routing.BuildError: Could not build url for endpoint 'user' with values ['username']. Did you mean 'main.user' instead?
2022-03-31 08:33:23,810 INFO: Microblog startup [in C:\Users\Administrator\PycharmProjects\microblog\app\__init__.py:74]
2022-03-31 08:41:55,254 INFO: Microblog startup [in C:\Users\Administrator\PycharmProjects\microblog\app\__init__.py:74]
2022-03-31 08:44:47,757 INFO: Microblog startup [in C:\Users\Administrator\PycharmProjects\microblog\app\__init__.py:74]
